
# Created by Ruins mod version 17.2 Ingame Parser
# authoring Player: Dartis_Xui

# TEMPLATE PARAMETER SETTINGS:
#
# criterion expression specifying mod ids required to load template
# may include plus (AND), minus (AND NOT), comma (OR), and parentheses
# all required mods listed must be present; no prohibited mods can be
requiredMods=
#
# likelihood this template will be chosen relative to all others
# e.g., a weight=6 template is chosen 3X as often as one with weight=2
weight=1
#
# list of dimensions in which this template may spawn, even if generic
# one or more dimension names, separated by commas (blank = all)
dimensionsToSpawnIn=
#
# list of other biomes in which this template may spawn
# biome corresponding to directory is always assumed, listed or not
# generic templates should leave this list empty
biomesToSpawnIn=
#
# criterion expression specifying types of biome where template spawns
# this is in addition to those explicitly listed as biomesToSpawnIn
# generic templates should leave this list empty
biomeTypesToSpawnIn=
#
# list of biomes in which this template may not spawn
# takes precedence over biomeTypesToSpawnIn, but NOT biomesToSpawnIn
# should be empty if biomeTypesToSpawnIn is empty
biomesToNotSpawnIn=
#
# depth template is pushed down into the surface when built
# offset is min/max range of random additional bury depth
embed_into_distance=10
random_height_offset=0,0
#
# whitelist/blacklist of block types on which template may be built
# specify one, not both; leave the other empty (both empty = allow all)
acceptable_target_blocks=
unacceptable_target_blocks=flowing_water,water
#
# size of template (#layers, #rows per layer, #blocks per row)
dimensions=10,19,19
#
# max number of missing blocks allowed in surface beneath template
allowable_overhang=0
#
# depth/height limit affected by terrain leveling
# also maximum bumpiness tolerated in surface beneath template
max_leveling=10
#
# padding applied to all sides of template horizontal footprint
# expands area affected by terrain leveling (-1 = no leveling)
leveling_buffer=-1
#
# do not rotate template randomly when built (1 = no rotation)
preventRotation=1
#
# treat water/lava blocks as air and protect them from rule0 (1 = yes)
preserve_water=0
preserve_lava=1
#
# minimum distance this template must have from instances of itself
uniqueMinDistance=0
#
# min/max distances this template can be from world spawn (0 = no limit)
# only applies to overworld--i.e., dimension 0
spawnMinDistance=0
spawnMaxDistance=0
#
# other template built nearby whenever this one is
# syntax: <name>;<relativeX>;<maxYdifference>;<relativeZ>[;<chance>]
# may be used more than once to specify multiple neighbors
adjoining_template=

rule1=0,100,minecraft:netherrack-0
rule2=0,100,minecraft:obsidian-0
rule3=0,100,minecraft:nether_brick-0
rule4=0,100,minecraft:sea_lantern-0
rule5=0,100,minecraft:lever-15
rule6=0,100,IInventory;minecraft:chest;sgcraft:zpm#64#0#0-3
rule7=0,100,IInventory;sgcraft:zpm_console;sgcraft:zpm#{AvailableEnergy:2.147463647E9d,loadedIntoCart:1b}#0#0-0
rule8=0,100,minecraft:stained_glass-14
rule9=0,100,minecraft:quartz_block-2
rule10=0,100,IInventory;minecraft:chest;sgcraft:pdd#64#0#0+sgcraft:gdo#64#0#1+sgcraft:tollan_phase_shift_device#64#0#2+sgcraft:sgirisupgrade#64#0#3+sgcraft:configurator#1#0#4-5
rule11=0,100,ChestGenHook:chests/simple_dungeon:5-5
rule12=0,100,minecraft:nether_brick_stairs-2
rule13=0,100,minecraft:nether_brick_stairs-0
rule14=0,100,minecraft:nether_brick_stairs-3
rule15=0,100,appliedenergistics2:chiseled_quartz_slab-0
rule16=0,100,sgcraft:stargatering-1
rule17=0,100,appliedenergistics2:chiseled_quartz_block-0
rule18=0,100,sgcraft:stargatering-0
rule19=0,100,IInventory;minecraft:chest;sgcraft:stargatering#11#0#0+sgcraft:stargatering#11#0#1+sgcraft:stargatering#11#0#2+sgcraft:stargatering#11#0#3+sgcraft:stargatering#11#0#4+sgcraft:stargatering#11#0#5+sgcraft:stargatering#11#0#6+sgcraft:stargatering#11#0#7+sgcraft:stargatering#11#1#9+sgcraft:stargatering#11#1#10+sgcraft:stargatering#11#1#11+sgcraft:stargatering#11#1#12+sgcraft:stargatering#11#1#13+sgcraft:stargatering#11#1#14+sgcraft:stargatering#11#1#15+sgcraft:stargatecontroller#11#0#18+sgcraft:stargatebase#11#0#19+sgcraft:zpm_console#11#0#25+sgcraft:zpm_hub#11#0#26-3
rule20=0,100,IInventory;sgcraft:stargatebase;minecraft:nether_brick#1#0#0+minecraft:nether_brick#1#0#1+minecraft:nether_brick#1#0#2+minecraft:nether_brick#1#0#3+minecraft:nether_brick#1#0#4-2
rule21=0,100,IInventory;sgcraft:stargatecontroller;minecraft:air#0#0#0+minecraft:air#0#0#1+minecraft:air#0#0#2+minecraft:air#0#0#3-2
rule22=0,100,minecraft:nether_brick_stairs-1
rule23=0,100,IInventory;minecraft:chest;minecraft:sandstone#64#2#0+minecraft:sandstone#64#2#1+minecraft:sandstone#64#1#2+minecraft:sandstone#64#1#3+sgcraft:naquadah#64#0#9+sgcraft:naquadahingot#64#0#10+sgcraft:naquadahblock#64#0#11+sgcraft:sgcontrollercrystal#64#0#18+sgcraft:sgcorecrystal#64#0#19+sgcraft:pegasus_upgrade#64#0#20-4
rule24=0,100,ChestGenHook:chests/simple_dungeon:5-4
rule25=0,100,minecraft:iron_trapdoor-6
rule26=0,100,minecraft:iron_door-3
rule27=0,100,minecraft:stone_slab-7
rule28=0,100,minecraft:iron_trapdoor-7
rule29=0,100,minecraft:quartz_block-1
rule30=0,100,minecraft:iron_door-8
rule31=0,100,teBlock;wall_banner;{Base:12}-3
rule32=2,100,WallSign:Made by Sakyo:null:Edited by:Dartis_Xui-5
rule33=2,100,WallSign:Taonas:null:null:null-3
rule34=2,100,WallSign:Taonas:Hot Bath:null:null-5
rule35=2,100,WallSign:Taonas:no Atlantis:null:null-2
rule36=2,100,WallSign:ZPM Free:null:null:null-3
rule37=2,100,WallSign:Congratulations:for find Taonas:null:null-3
rule38=2,100,WallSign:Force Field:activated:No touch ZPM:null-3
rule39=2,100,WallSign:Taonas:First Colony:null:null-2
rule40=2,100,WallSign:Made by Sakyo:null:Edited by:Dartis_Xui-2
rule41=2,100,WallSign:Taonas:Population: 0:null-4
rule42=2,100,WallSign:Taonas:Hot Place:null:null-2
rule43=2,100,WallSign:Made by Sakyo:null:Edited by:Dartis_Xui-4
rule44=0,100,minecraft:lava-0

layer
1,1,1,1,1,1,1,1,1,1,1,1,1,1,1,1,1,1,1
1,1,1,1,1,1,1,1,2,2,2,1,1,1,1,1,1,1,1
1,1,1,1,1,1,2,2,3,3,3,2,2,1,1,1,1,1,1
1,1,1,1,1,2,3,3,3,3,3,3,3,2,1,1,1,1,1
1,1,1,1,2,3,3,3,3,3,3,3,3,3,2,1,1,1,1
1,1,1,2,3,3,3,3,3,3,3,3,3,3,3,2,1,1,1
1,1,2,3,3,3,3,3,3,3,3,3,3,3,3,3,2,1,1
1,1,2,3,3,3,3,3,3,3,4,4,4,3,3,3,2,1,1
1,2,3,3,6,3,3,3,3,4,4,5,3,4,3,3,3,2,1
1,2,3,3,3,3,3,3,3,7,4,3,3,4,3,3,3,2,1
1,2,3,3,3,3,3,3,3,4,4,5,3,4,3,3,3,2,1
1,1,2,3,3,3,3,3,3,3,4,4,4,3,3,3,2,1,1
1,1,2,3,3,3,3,3,3,3,3,3,3,3,3,3,2,1,1
1,1,2,2,3,3,3,3,3,3,3,3,3,3,3,2,1,1,1
1,1,1,1,2,3,3,3,3,3,3,3,3,3,2,1,1,1,1
1,1,1,1,1,2,3,3,3,3,3,3,3,2,1,1,1,1,1
1,1,1,1,1,1,2,2,3,3,3,2,2,1,1,1,1,1,1
1,1,1,1,1,1,1,1,2,2,2,1,1,1,1,1,1,1,1
1,1,1,1,1,1,1,1,1,1,1,1,1,1,1,1,1,1,1
endlayer

layer
1,1,1,1,1,1,1,1,1,1,1,1,1,1,1,1,1,1,1
1,1,1,1,1,1,1,1,2,2,2,1,1,1,1,1,1,1,1
1,1,1,1,1,1,2,2,8,8,8,2,2,1,1,1,1,1,1
1,1,1,1,1,2,8,8,9,0,9,8,8,2,1,1,1,1,1
1,1,1,1,2,8,0,0,0,0,0,11,10,8,2,1,1,1,1
1,1,1,2,8,0,0,0,0,0,0,0,0,0,8,2,1,1,1
1,1,2,8,14,13,12,0,0,0,0,0,0,0,0,8,2,1,1
1,1,2,8,14,16,12,0,0,0,15,15,15,0,0,8,2,1,1
1,2,8,0,14,18,12,0,0,15,17,17,17,15,0,0,8,2,1
1,2,8,0,14,20,12,0,0,15,17,4,17,15,0,19,8,2,1
1,2,8,0,14,18,12,0,0,15,17,17,17,15,0,0,8,2,1
1,1,2,8,14,16,12,0,0,0,15,15,15,0,0,8,2,1,1
1,1,2,8,14,22,22,0,0,0,21,0,0,0,0,8,2,1,1
1,1,2,2,8,0,0,0,0,0,0,0,0,0,8,2,1,1,1
1,1,1,1,2,8,0,0,0,0,0,24,23,8,2,1,1,1,1
1,1,1,1,1,2,8,8,9,0,9,8,8,2,1,1,1,1,1
1,1,1,1,1,1,2,2,8,8,8,2,2,1,1,1,1,1,1
1,1,1,1,1,1,1,1,2,2,2,1,1,1,1,1,1,1,1
1,1,1,1,1,1,1,1,1,1,1,1,1,1,1,1,1,1,1
endlayer

layer
1,1,1,1,1,1,1,1,1,1,1,1,1,1,1,1,1,1,1
1,1,1,1,1,1,1,1,2,2,2,1,1,1,1,1,1,1,1
1,1,1,1,1,1,2,2,8,8,8,2,2,1,1,1,1,1,1
1,1,1,1,1,2,8,8,9,0,9,8,8,2,1,1,1,1,1
1,1,1,1,2,8,0,0,0,0,0,0,0,8,2,1,1,1,1
1,1,1,2,8,0,0,0,0,0,0,0,0,0,8,2,1,1,1
1,1,2,8,0,0,0,0,0,0,0,0,0,0,0,8,2,1,1
1,1,2,8,0,18,0,0,0,0,0,0,0,0,0,8,2,1,1
1,2,8,0,0,0,0,0,0,0,0,25,0,0,0,0,8,2,1
1,2,8,0,0,0,0,0,0,0,0,27,26,0,0,0,8,2,1
1,2,8,0,0,0,0,0,0,0,0,28,0,0,0,0,8,2,1
1,1,2,8,0,18,0,0,0,0,0,0,0,0,0,8,2,1,1
1,1,2,8,0,0,0,0,0,0,0,0,0,0,0,8,2,1,1
1,1,2,2,8,0,0,0,0,0,0,0,0,0,8,2,1,1,1
1,1,1,1,2,8,0,0,0,0,0,0,0,8,2,1,1,1,1
1,1,1,1,1,2,8,8,9,0,9,8,8,2,1,1,1,1,1
1,1,1,1,1,1,2,2,8,8,8,2,2,1,1,1,1,1,1
1,1,1,1,1,1,1,1,2,2,2,1,1,1,1,1,1,1,1
1,1,1,1,1,1,1,1,1,1,1,1,1,1,1,1,1,1,1
endlayer

layer
1,1,1,1,1,1,1,1,1,1,1,1,1,1,1,1,1,1,1
1,1,1,1,1,1,1,1,2,2,2,1,1,1,1,1,1,1,1
1,1,1,1,1,1,2,2,8,8,8,2,2,1,1,1,1,1,1
1,1,1,1,1,2,8,8,9,29,9,8,8,2,1,1,1,1,1
1,1,1,1,2,8,0,0,0,0,0,0,0,8,2,1,1,1,1
1,1,1,2,8,0,0,0,0,0,0,0,0,0,8,2,1,1,1
1,1,2,8,0,0,0,0,0,0,0,0,0,0,0,8,2,1,1
1,1,2,8,0,16,0,0,0,0,0,0,0,0,0,8,2,1,1
1,2,8,0,0,0,0,0,0,0,0,0,0,0,0,0,8,2,1
1,2,8,0,0,0,0,0,0,0,0,31,30,0,0,0,8,2,1
1,2,8,0,0,0,0,0,0,0,0,0,0,0,0,0,8,2,1
1,1,2,8,0,16,0,0,0,0,0,0,0,0,0,8,2,1,1
1,1,2,8,0,0,0,0,0,0,0,0,0,0,0,8,2,1,1
1,1,2,2,8,0,0,0,0,0,0,0,0,0,8,2,1,1,1
1,1,1,1,2,8,0,0,0,0,0,0,0,8,2,1,1,1,1
1,1,1,1,1,2,8,8,9,29,9,8,8,2,1,1,1,1,1
1,1,1,1,1,1,2,2,8,8,8,2,2,1,1,1,1,1,1
1,1,1,1,1,1,1,1,2,2,2,1,1,1,1,1,1,1,1
1,1,1,1,1,1,1,1,1,1,1,1,1,1,1,1,1,1,1
endlayer

layer
1,1,1,1,1,1,1,1,1,1,1,1,1,1,1,1,1,1,1
1,1,1,1,1,1,1,1,2,2,2,1,1,1,1,1,1,1,1
1,1,1,1,1,1,2,2,8,8,8,2,2,1,1,1,1,1,1
1,1,1,1,1,2,8,8,0,0,0,8,8,2,1,1,1,1,1
1,1,1,1,2,8,0,0,0,0,0,0,0,8,2,1,1,1,1
1,1,1,2,8,0,0,0,0,0,0,0,0,0,8,2,1,1,1
1,1,2,8,0,0,0,0,0,0,0,0,0,0,0,8,2,1,1
1,1,2,8,0,18,0,0,0,0,0,0,0,0,0,8,2,1,1
1,2,8,0,0,0,0,0,0,0,0,0,0,0,0,0,8,2,1
1,2,8,0,0,0,0,0,0,0,0,0,0,0,0,0,8,2,1
1,2,8,0,0,0,0,0,0,0,0,0,0,0,0,0,8,2,1
1,1,2,8,0,18,0,0,0,0,0,0,0,0,0,8,2,1,1
1,1,2,8,0,0,0,0,0,0,0,0,0,0,0,8,2,1,1
1,1,2,2,8,0,0,0,0,0,0,0,0,0,8,2,1,1,1
1,1,1,1,2,8,0,0,0,0,0,0,0,8,2,1,1,1,1
1,1,1,1,1,2,8,8,0,0,0,8,8,2,1,1,1,1,1
1,1,1,1,1,1,2,2,8,8,8,2,2,1,1,1,1,1,1
1,1,1,1,1,1,1,1,2,2,2,1,1,1,1,1,1,1,1
1,1,1,1,1,1,1,1,1,1,1,1,1,1,1,1,1,1,1
endlayer

layer
1,1,1,1,1,1,1,1,1,1,1,1,1,1,1,1,1,1,1
1,1,1,1,1,1,1,1,2,2,2,1,1,1,1,1,1,1,1
1,1,1,1,1,1,2,2,8,8,8,2,2,1,1,1,1,1,1
1,1,1,1,1,2,8,8,0,0,0,8,8,2,1,1,1,1,1
1,1,1,1,2,8,0,0,0,0,0,0,0,8,2,1,1,1,1
1,1,1,2,8,0,0,0,0,0,0,0,0,0,8,2,1,1,1
1,1,2,8,0,0,0,0,0,0,0,0,0,0,0,8,2,1,1
1,1,2,8,0,16,0,0,0,0,0,0,0,0,0,8,2,1,1
1,2,8,0,0,18,0,0,0,0,0,0,0,0,0,0,8,2,1
1,2,8,0,0,16,0,0,0,0,0,0,0,0,0,0,8,2,1
1,2,8,0,0,18,0,0,0,0,0,0,0,0,0,0,8,2,1
1,1,2,8,0,16,0,0,0,0,0,0,0,0,0,8,2,1,1
1,1,2,8,0,0,0,0,0,0,0,0,0,0,0,8,2,1,1
1,1,2,2,8,0,0,0,0,0,0,0,0,0,8,2,1,1,1
1,1,1,1,2,8,0,0,0,0,0,0,0,8,2,1,1,1,1
1,1,1,1,1,2,8,8,0,0,0,8,8,2,1,1,1,1,1
1,1,1,1,1,1,2,2,8,8,8,2,2,1,1,1,1,1,1
1,1,1,1,1,1,1,1,2,2,2,1,1,1,1,1,1,1,1
1,1,1,1,1,1,1,1,1,1,1,1,1,1,1,1,1,1,1
endlayer

layer
1,1,1,1,1,1,1,1,1,1,1,1,1,1,1,1,1,1,1
1,1,1,1,1,1,1,1,2,2,2,1,1,1,1,1,1,1,1
1,1,1,1,1,1,2,2,8,8,8,2,2,1,1,1,1,1,1
1,1,1,1,1,2,8,8,0,0,0,8,8,2,1,1,1,1,1
1,1,1,1,2,8,0,0,0,0,0,0,0,8,2,1,1,1,1
1,1,1,2,8,0,0,0,0,0,0,0,0,0,8,2,1,1,1
1,1,2,8,0,0,0,0,0,0,0,0,0,0,0,8,2,1,1
1,1,2,8,0,0,0,0,0,0,0,0,0,0,0,8,2,1,1
1,2,8,0,0,0,0,0,0,0,0,0,0,0,0,0,8,2,1
1,2,8,0,0,0,0,0,0,0,0,0,0,0,0,0,8,2,1
1,2,8,0,0,0,0,0,0,0,0,0,0,0,0,0,8,2,1
1,1,2,8,0,0,0,0,0,0,0,0,0,0,0,8,2,1,1
1,1,2,8,0,0,0,0,0,0,0,0,0,0,0,8,2,1,1
1,1,2,2,8,0,0,0,0,0,0,0,0,0,8,2,1,1,1
1,1,1,1,2,8,0,0,0,0,0,0,0,8,2,1,1,1,1
1,1,1,1,1,2,8,8,0,0,0,8,8,2,1,1,1,1,1
1,1,1,1,1,1,2,2,8,8,8,2,2,1,1,1,1,1,1
1,1,1,1,1,1,1,1,2,2,2,1,1,1,1,1,1,1,1
1,1,1,1,1,1,1,1,1,1,1,1,1,1,1,1,1,1,1
endlayer

layer
1,1,1,1,1,1,1,1,1,1,1,1,1,1,1,1,1,1,1
1,1,1,1,1,1,1,1,2,2,2,1,1,1,1,1,1,1,1
1,1,1,1,1,1,2,2,8,8,8,2,2,1,1,1,1,1,1
1,1,1,1,1,2,8,8,8,8,8,8,8,2,1,1,1,1,1
1,1,1,1,2,8,8,8,8,8,8,8,8,2,2,1,1,1,1
1,1,1,2,2,8,8,8,8,8,8,8,8,8,2,2,1,1,1
1,1,2,2,8,8,8,8,8,8,8,8,8,8,8,2,2,1,1
1,1,2,8,8,8,8,8,8,8,0,8,8,8,8,2,2,1,1
1,2,8,8,8,8,8,8,8,0,0,0,8,8,8,8,8,2,1
1,2,8,8,8,8,8,0,0,0,0,0,0,8,8,8,8,2,1
1,2,8,8,8,8,8,8,8,0,0,0,8,8,8,8,8,2,1
1,1,2,8,8,8,8,8,8,8,0,8,8,8,8,2,2,1,1
1,1,2,2,8,8,8,8,8,8,8,8,8,8,8,2,2,1,1
1,1,2,2,2,8,8,8,8,8,8,8,8,8,2,2,1,1,1
1,1,1,1,2,8,8,8,8,8,8,8,8,2,2,1,1,1,1
1,1,1,1,1,2,8,8,8,8,8,8,8,2,1,1,1,1,1
1,1,1,1,1,1,2,2,8,8,8,2,2,1,1,1,1,1,1
1,1,1,1,1,1,1,1,2,2,2,1,1,1,1,1,1,1,1
1,1,1,1,1,1,1,1,1,1,1,1,1,1,1,1,1,1,1
endlayer

layer
1,1,1,1,1,1,1,1,1,1,1,1,1,1,1,1,1,1,1
1,1,1,1,1,1,1,1,2,2,2,1,1,1,1,1,1,1,1
1,1,1,1,1,1,1,2,2,2,2,2,2,1,1,1,1,1,1
1,1,1,1,1,2,2,2,2,2,2,2,2,2,1,1,1,1,1
1,1,1,1,2,2,2,2,2,2,2,2,2,2,2,1,1,1,1
1,1,1,2,2,2,2,2,2,2,2,2,2,2,2,2,1,1,1
1,1,2,2,2,2,2,2,2,2,2,2,2,2,2,2,2,1,1
1,1,2,2,2,2,2,2,2,2,32,2,2,2,2,2,2,1,1
1,2,2,2,2,2,2,2,2,35,34,33,2,2,2,2,2,2,1
1,2,2,2,2,2,2,2,40,39,38,37,36,2,2,2,2,2,1
1,2,2,2,2,2,2,2,2,42,41,33,2,2,2,2,2,2,1
1,1,2,2,2,2,2,2,2,2,43,2,2,2,2,2,2,1,1
1,1,2,2,2,2,2,2,2,2,2,2,2,2,2,2,2,1,1
1,1,2,2,2,2,2,2,2,2,2,2,2,2,2,2,1,1,1
1,1,1,1,2,2,2,2,2,2,2,2,2,2,2,1,1,1,1
1,1,1,1,1,2,2,2,2,2,2,2,2,2,1,1,1,1,1
1,1,1,1,1,1,2,2,2,2,2,2,2,1,1,1,1,1,1
1,1,1,1,1,1,1,1,2,2,2,1,1,1,1,1,1,1,1
1,1,1,1,1,1,1,1,1,1,1,1,1,1,1,1,1,1,1
endlayer

layer
1,1,1,1,1,1,1,1,1,1,1,1,1,1,1,1,1,1,1
1,1,1,1,1,1,1,1,1,1,1,1,1,1,1,1,1,1,1
1,1,1,1,1,1,1,1,1,1,1,1,1,1,1,1,1,1,1
1,1,1,1,1,1,1,1,1,1,1,1,1,1,1,1,1,1,1
1,1,1,1,1,1,1,1,1,44,44,1,1,1,1,1,1,1,1
1,1,1,1,1,1,1,1,44,44,44,1,1,44,1,1,1,1,1
1,1,1,1,1,1,44,44,44,44,44,44,44,44,1,1,1,1,1
1,1,1,1,1,1,44,44,44,44,44,44,44,44,1,1,1,1,1
1,1,1,1,1,44,44,44,44,44,44,44,44,44,44,44,1,1,1
1,1,1,1,44,44,44,44,44,44,44,44,44,44,44,44,1,1,1
1,1,1,1,44,44,44,44,44,44,44,44,44,44,44,44,1,1,1
1,1,1,1,1,1,44,44,44,44,44,44,44,1,1,44,1,1,1
1,1,1,1,1,1,44,44,44,44,44,44,44,1,1,1,1,1,1
1,1,1,1,1,1,1,1,1,44,44,44,1,1,1,1,1,1,1
1,1,1,1,1,1,1,1,1,44,1,1,1,1,1,1,1,1,1
1,1,1,1,1,1,1,1,1,1,1,1,1,1,1,1,1,1,1
1,1,1,1,1,1,1,1,1,1,1,1,1,1,1,1,1,1,1
1,1,1,1,1,1,1,1,1,1,1,1,1,1,1,1,1,1,1
1,1,1,1,1,1,1,1,1,1,1,1,1,1,1,1,1,1,1
endlayer

