
# Created by Ruins mod version 17.2 Ingame Parser
# authoring Player: Dartis_Xui

# TEMPLATE PARAMETER SETTINGS:
#
# criterion expression specifying mod ids required to load template
# may include plus (AND), minus (AND NOT), comma (OR), and parentheses
# all required mods listed must be present; no prohibited mods can be
requiredMods=
#
# likelihood this template will be chosen relative to all others
# e.g., a weight=6 template is chosen 3X as often as one with weight=2
weight=1
#
# list of dimensions in which this template may spawn, even if generic
# one or more dimension names, separated by commas (blank = all)
dimensionsToSpawnIn=
#
# list of other biomes in which this template may spawn
# biome corresponding to directory is always assumed, listed or not
# generic templates should leave this list empty
biomesToSpawnIn=
#
# criterion expression specifying types of biome where template spawns
# this is in addition to those explicitly listed as biomesToSpawnIn
# generic templates should leave this list empty
biomeTypesToSpawnIn=
#
# list of biomes in which this template may not spawn
# takes precedence over biomeTypesToSpawnIn, but NOT biomesToSpawnIn
# should be empty if biomeTypesToSpawnIn is empty
biomesToNotSpawnIn=
#
# depth template is pushed down into the surface when built
# offset is min/max range of random additional bury depth
embed_into_distance=0
random_height_offset=0,0
#
# whitelist/blacklist of block types on which template may be built
# specify one, not both; leave the other empty (both empty = allow all)
acceptable_target_blocks=
unacceptable_target_blocks=flowing_water,water,flowing_lava,lava
#
# size of template (#layers, #rows per layer, #blocks per row)
dimensions=28,11,11
#
# max number of missing blocks allowed in surface beneath template
allowable_overhang=0
#
# depth/height limit affected by terrain leveling
# also maximum bumpiness tolerated in surface beneath template
max_leveling=2
#
# padding applied to all sides of template horizontal footprint
# expands area affected by terrain leveling (-1 = no leveling)
leveling_buffer=0
#
# do not rotate template randomly when built (1 = no rotation)
preventRotation=0
#
# treat water/lava blocks as air and protect them from rule0 (1 = yes)
preserve_water=0
preserve_lava=0
#
# minimum distance this template must have from instances of itself
uniqueMinDistance=0
#
# min/max distances this template can be from world spawn (0 = no limit)
# only applies to overworld--i.e., dimension 0
spawnMinDistance=0
spawnMaxDistance=0
#
# other template built nearby whenever this one is
# syntax: <name>;<relativeX>;<maxYdifference>;<relativeZ>[;<chance>]
# may be used more than once to specify multiple neighbors
adjoining_template=

rule1=0,100,minecraft:stonebrick-3
rule2=0,100,minecraft:cobblestone-0
rule3=0,100,minecraft:grass-0
rule4=0,100,minecraft:dirt-0
rule5=0,100,minecraft:mossy_cobblestone-0
rule6=0,100,minecraft:mob_spawner-0
rule7=0,100,minecraft:birch_fence-0
rule8=0,100,minecraft:tallgrass-1
rule9=0,100,minecraft:double_stone_slab-0
rule10=0,100,minecraft:web-0
rule11=0,100,IInventory;minecraft:chest;lucraftcore:ore_uru#10#0#0+heroesexpansion:mjolnir_head_cast#1#0#1+heroesexpansion:ultimate_mjolnir_head_cast#1#0#2+heroesexpansion:stormbreaker_head_cast#1#0#3+heroesexpansion:thor_iw_chest#1#0#4+heroesexpansion:thor_iw_legs#1#0#5+heroesexpansion:thor_iw_boots#1#0#6-2
rule12=0,100,minecraft:ladder-3
rule13=0,100,minecraft:birch_stairs-6
rule14=0,100,minecraft:birch_stairs-3
rule15=0,100,minecraft:stone_stairs-3
rule16=0,100,minecraft:stone_stairs-0
rule17=0,100,minecraft:stone_stairs-1
rule18=0,100,minecraft:stone_stairs-2
rule19=0,100,minecraft:birch_stairs-4
rule20=1,100,minecraft:redstone_torch-5
rule21=0,100,minecraft:stone_stairs-7
rule22=0,100,minecraft:stone_stairs-4
rule23=0,100,minecraft:stone_stairs-5
rule24=0,100,minecraft:stone_stairs-6
rule25=0,100,minecraft:birch_stairs-1
rule26=0,100,minecraft:stone_brick_stairs-4
rule27=0,100,minecraft:stone_brick_stairs-6
rule28=0,100,minecraft:stone_brick_stairs-7
rule29=0,100,minecraft:stone_brick_stairs-5
rule30=0,100,minecraft:log-2
rule31=0,100,minecraft:log-10
rule32=0,100,minecraft:log-6
rule33=0,100,minecraft:planks-2
rule34=0,100,minecraft:stained_glass_pane-0
rule35=0,100,minecraft:birch_stairs-7
rule36=0,100,minecraft:wooden_slab-10
rule37=0,100,ChestGenHook:chests/simple_dungeon:5-2
rule38=0,100,minecraft:birch_stairs-0
rule39=0,100,minecraft:birch_door-1
rule40=0,100,minecraft:wooden_slab-2
rule41=0,100,minecraft:carpet-0
rule42=0,100,minecraft:birch_door-8
rule43=0,100,minecraft:wool-8
rule44=0,100,minecraft:birch_stairs-2
rule45=0,100,minecraft:birch_stairs-5

layer
1,2,2,0,0,0,0,0,2,2,1
2,2,2,0,0,0,0,0,2,2,2
2,2,2,0,0,0,0,0,2,2,2
0,0,0,0,0,0,0,0,0,0,0
0,0,0,0,0,0,0,0,0,0,0
0,0,0,0,0,0,0,0,0,0,0
0,0,0,0,0,0,0,0,0,0,0
0,0,0,0,0,0,0,0,0,0,0
2,2,2,0,0,0,0,0,2,2,2
2,2,2,0,0,0,0,0,2,2,2
1,2,2,0,0,0,0,0,2,2,1
endlayer

layer
1,2,2,0,0,0,0,0,2,2,1
2,2,2,0,0,0,0,0,2,2,2
2,2,2,0,0,0,0,0,2,2,2
0,0,0,0,0,0,0,0,0,0,0
0,0,0,0,0,0,0,0,0,0,0
0,0,0,0,0,0,0,0,0,0,0
0,0,0,0,0,0,0,0,0,0,0
0,0,0,0,0,0,0,0,0,0,0
2,2,2,0,0,0,0,0,2,2,2
2,2,2,0,0,0,0,0,2,2,2
1,2,2,0,0,0,0,0,2,2,1
endlayer

layer
1,2,2,0,0,0,0,0,2,2,1
2,2,2,0,0,0,0,0,2,2,2
2,2,2,0,0,0,0,0,2,2,2
0,0,0,0,0,0,0,0,0,0,0
0,0,0,0,0,0,0,0,0,0,0
0,0,0,0,0,0,0,0,0,0,0
0,0,0,0,0,0,0,0,0,0,0
0,0,0,0,0,0,0,0,0,0,0
2,2,2,0,0,0,0,0,2,2,2
2,2,2,0,0,0,0,0,2,2,2
1,2,2,0,0,0,0,0,2,2,1
endlayer

layer
1,2,2,0,0,0,0,0,2,2,1
2,2,2,0,0,0,0,0,2,2,2
2,2,2,0,0,0,0,0,2,2,2
0,0,0,0,0,0,0,0,0,0,0
0,0,0,0,0,0,0,0,0,0,0
0,0,0,0,0,0,0,0,0,0,0
0,0,0,0,0,0,0,0,0,0,0
0,0,0,0,0,0,0,0,0,0,0
2,2,2,0,0,0,0,0,2,2,2
2,2,2,0,0,0,0,0,2,2,2
1,2,2,0,0,0,0,0,2,2,1
endlayer

layer
1,2,2,0,0,0,0,0,2,2,1
2,2,2,0,0,0,0,0,2,2,2
2,2,2,0,0,0,0,0,2,2,2
0,0,0,0,0,0,0,0,0,0,0
0,0,0,0,0,0,0,0,0,0,0
0,0,0,0,0,0,0,0,0,0,0
0,0,0,0,0,0,0,0,0,0,0
0,0,0,0,0,0,0,0,0,0,0
2,2,2,0,0,0,0,0,2,2,2
2,2,2,0,0,0,0,0,2,2,2
1,2,2,0,0,0,0,0,2,2,1
endlayer

layer
1,2,2,2,2,2,2,2,2,2,1
2,2,2,2,2,2,2,2,2,2,2
2,2,2,2,2,2,2,2,2,2,2
2,2,2,2,2,2,2,2,2,2,2
2,2,2,2,2,2,2,2,2,2,2
2,2,2,2,2,2,2,2,2,2,2
2,2,2,2,2,2,2,2,2,2,2
2,2,2,2,2,2,2,2,2,2,2
2,2,2,2,2,2,2,2,2,2,2
2,2,2,2,2,2,2,2,2,2,2
1,2,2,2,2,2,2,2,2,2,1
endlayer

layer
1,2,2,2,2,2,2,2,2,2,1
2,3,3,3,3,3,3,3,3,3,2
2,3,3,4,3,3,4,4,4,3,2
2,3,4,2,2,2,2,2,4,3,2
2,3,3,2,5,5,5,2,3,3,2
2,3,3,2,5,6,5,2,3,3,2
2,3,4,2,5,5,5,2,4,3,2
2,3,4,2,2,2,2,2,4,3,2
2,3,4,4,3,3,3,3,3,3,2
2,3,3,3,3,1,1,3,3,3,2
1,2,2,2,1,1,1,2,2,2,1
endlayer

layer
1,7,7,7,7,7,7,7,7,7,1
7,8,0,8,0,8,8,0,0,8,7
7,0,0,3,0,0,3,3,3,0,7
7,0,3,9,2,2,2,9,3,8,7
7,0,8,2,10,11,10,2,0,0,7
7,8,0,2,0,10,0,2,8,8,7
7,0,3,2,10,0,12,2,3,0,7
7,0,4,9,2,2,2,9,3,0,7
7,8,3,3,0,8,0,8,0,8,7
7,8,0,0,8,0,0,14,13,7,7
1,7,7,7,1,0,1,7,7,7,1
endlayer

layer
7,7,0,0,0,0,0,0,0,7,7
7,0,0,0,0,0,0,0,0,0,7
0,0,0,0,0,0,0,0,8,0,0
0,0,0,9,2,2,2,9,8,0,0
0,0,0,2,0,10,0,2,0,0,0
0,0,0,2,0,0,0,2,0,0,0
0,0,8,2,0,0,12,2,8,0,0
0,0,3,9,2,2,2,9,8,0,0
0,0,8,8,0,0,0,0,0,0,0
7,0,0,0,0,0,0,0,14,13,7
7,7,0,7,7,0,7,7,0,7,7
endlayer

layer
0,0,0,0,0,0,0,0,0,0,0
0,0,0,0,0,0,0,0,0,0,0
0,0,0,0,0,0,0,0,0,0,0
0,0,0,9,2,15,2,9,0,0,0
0,0,0,2,0,0,0,2,0,0,0
0,0,0,17,0,0,0,16,0,0,0
0,0,0,2,0,0,12,2,0,0,0
0,0,8,9,2,18,2,9,0,0,0
0,0,0,0,0,0,0,0,0,19,0
0,0,0,0,0,0,0,0,0,14,0
0,0,0,0,20,0,20,0,0,0,0
endlayer

layer
0,0,0,0,0,0,0,0,0,0,0
0,0,0,0,0,0,0,0,0,0,0
0,0,0,0,0,0,0,0,0,0,0
0,0,0,9,2,21,2,9,0,0,0
0,0,0,2,0,0,0,2,0,0,0
0,0,0,23,0,0,0,22,0,0,0
0,0,0,2,0,0,12,2,0,0,0
0,0,0,9,2,24,2,9,0,19,0
0,0,0,0,0,0,0,0,0,25,0
0,0,0,0,0,0,0,0,0,0,0
0,0,0,0,0,0,0,0,0,0,0
endlayer

layer
0,0,0,0,0,0,0,0,0,0,0
0,0,0,0,0,0,0,0,0,0,0
0,0,0,26,0,0,0,26,0,0,0
0,0,28,1,2,2,2,1,27,0,0
0,0,0,2,0,0,0,2,0,0,0
0,0,0,2,0,0,0,2,7,7,0
0,0,0,2,0,0,12,2,0,19,0
0,0,28,1,2,2,2,1,27,25,0
0,0,0,29,0,0,0,29,0,0,0
0,0,0,0,0,0,0,0,0,0,0
0,0,0,0,0,0,0,0,0,0,0
endlayer

layer
0,0,0,0,0,0,0,0,0,0,0
0,0,0,0,0,0,0,0,0,0,0
0,0,30,31,31,31,31,31,30,0,0
0,0,32,30,30,30,30,30,32,0,0
0,0,32,30,33,33,33,30,32,0,0
0,0,32,30,33,33,33,30,32,19,0
0,0,32,30,33,33,0,30,32,25,0
0,0,32,30,30,30,30,30,32,0,0
0,0,30,31,31,31,31,31,30,0,0
0,0,0,0,0,0,0,0,0,0,0
0,0,0,0,0,0,0,0,0,0,0
endlayer

layer
0,0,0,0,0,0,0,0,0,0,0
0,0,0,0,0,0,0,0,0,0,0
0,0,30,33,33,34,33,33,30,0,0
0,0,33,37,13,36,35,0,33,0,0
0,0,33,0,0,38,0,0,33,7,0
0,0,34,0,0,0,0,39,0,0,0
0,0,33,0,40,0,0,0,33,0,0
0,0,33,7,40,0,0,12,33,0,0
0,0,30,33,33,34,33,33,30,0,0
0,0,0,0,0,0,0,0,0,0,0
0,0,0,0,0,0,0,0,0,0,0
endlayer

layer
0,0,0,0,0,0,0,0,0,0,0
0,0,0,0,0,0,0,0,0,0,0
0,0,30,33,33,34,33,33,30,0,0
0,0,33,0,20,41,0,0,33,0,0
0,0,33,0,0,0,0,0,33,20,0
0,0,34,0,0,0,0,42,0,0,0
0,0,33,0,0,0,0,0,33,0,0
0,0,33,41,0,0,0,12,33,0,0
0,0,30,33,33,34,33,33,30,0,0
0,0,0,0,0,0,0,0,0,0,0
0,0,0,0,0,0,0,0,0,0,0
endlayer

layer
0,0,0,0,0,0,0,0,0,0,0
0,0,0,0,0,0,0,0,0,0,0
0,0,30,33,33,43,33,33,30,0,0
0,0,33,0,0,0,0,0,33,0,0
0,0,33,0,0,0,0,0,33,0,0
0,0,43,0,0,0,0,0,43,0,0
0,0,33,0,0,0,0,0,33,0,0
0,0,33,0,0,0,0,12,33,0,0
0,0,30,33,33,43,33,33,30,0,0
0,0,0,0,0,0,0,0,0,0,0
0,0,0,0,0,0,0,0,0,0,0
endlayer

layer
0,0,0,0,0,0,0,0,0,0,0
0,0,0,0,0,0,0,0,0,0,0
0,0,30,31,31,31,31,31,30,0,0
0,0,32,36,36,36,36,36,32,0,0
0,0,32,36,0,0,0,36,32,0,0
0,0,32,36,0,0,0,36,32,0,0
0,0,32,36,0,0,0,36,32,0,0
0,0,32,36,36,36,36,12,32,0,0
0,0,30,31,31,31,31,31,30,0,0
0,0,0,0,0,0,0,0,0,0,0
0,0,0,0,0,0,0,0,0,0,0
endlayer

layer
0,0,0,0,0,0,0,0,0,0,0
0,14,38,38,38,38,38,38,38,38,0
0,14,33,33,33,33,33,33,33,44,0
0,14,33,0,0,0,0,0,33,44,0
0,14,33,0,0,0,0,0,33,44,0
0,14,33,0,0,6,0,0,33,44,0
0,14,33,0,0,0,0,0,33,44,0
0,14,33,0,0,0,0,0,33,44,0
0,14,33,33,33,33,33,33,33,44,0
0,25,25,25,25,25,25,25,25,44,0
0,0,0,0,0,0,0,0,0,0,0
endlayer

layer
0,0,0,0,0,0,0,0,0,0,0
0,0,0,0,0,0,0,0,0,0,0
0,0,33,33,33,43,33,33,33,0,0
0,0,33,10,0,0,0,0,33,0,0
0,0,33,0,0,7,0,0,33,0,0
0,0,43,0,7,7,7,0,43,0,0
0,0,33,10,0,7,10,10,33,0,0
0,0,33,10,10,0,10,10,33,0,0
0,0,33,33,33,43,33,33,33,0,0
0,0,0,0,0,0,0,0,0,0,0
0,0,0,0,0,0,0,0,0,0,0
endlayer

layer
0,0,0,0,0,0,0,0,0,0,0
0,0,0,0,0,0,0,0,0,0,0
0,0,14,38,33,43,33,38,38,0,0
0,0,14,45,45,0,45,35,44,0,0
0,0,33,13,0,20,0,35,33,0,0
0,0,43,0,20,7,20,0,43,0,0
0,0,33,13,0,20,0,35,33,0,0
0,0,14,13,19,0,19,19,44,0,0
0,0,25,25,33,43,33,25,44,0,0
0,0,0,0,0,0,0,0,0,0,0
0,0,0,0,0,0,0,0,0,0,0
endlayer

layer
0,0,0,0,0,0,0,0,0,0,0
0,0,0,0,0,0,0,0,0,0,0
0,0,0,0,14,33,44,0,0,0,0
0,0,0,33,33,0,33,33,0,0,0
0,0,38,33,10,0,10,33,38,0,0
0,0,33,0,0,7,10,10,33,0,0
0,0,25,33,10,0,0,33,25,0,0
0,0,0,33,33,0,33,33,0,0,0
0,0,0,0,14,33,44,0,0,0,0
0,0,0,0,0,0,0,0,0,0,0
0,0,0,0,0,0,0,0,0,0,0
endlayer

layer
0,0,0,0,0,0,0,0,0,0,0
0,0,0,0,0,0,0,0,0,0,0
0,0,0,0,0,0,0,0,0,0,0
0,0,0,14,38,38,38,38,0,0,0
0,0,0,14,45,45,35,44,0,0,0
0,0,0,14,13,7,35,44,0,0,0
0,0,0,14,13,19,19,44,0,0,0
0,0,0,25,25,25,25,44,0,0,0
0,0,0,0,0,0,0,0,0,0,0
0,0,0,0,0,0,0,0,0,0,0
0,0,0,0,0,0,0,0,0,0,0
endlayer

layer
0,0,0,0,0,0,0,0,0,0,0
0,0,0,0,0,0,0,0,0,0,0
0,0,0,0,0,0,0,0,0,0,0
0,0,0,0,0,0,0,0,0,0,0
0,0,0,0,33,33,33,0,0,0,0
0,0,0,0,33,7,33,0,0,0,0
0,0,0,0,33,33,33,0,0,0,0
0,0,0,0,0,0,0,0,0,0,0
0,0,0,0,0,0,0,0,0,0,0
0,0,0,0,0,0,0,0,0,0,0
0,0,0,0,0,0,0,0,0,0,0
endlayer

layer
0,0,0,0,0,0,0,0,0,0,0
0,0,0,0,0,0,0,0,0,0,0
0,0,0,0,0,0,0,0,0,0,0
0,0,0,0,0,0,0,0,0,0,0
0,0,0,0,14,38,38,0,0,0,0
0,0,0,0,14,33,44,0,0,0,0
0,0,0,0,25,25,44,0,0,0,0
0,0,0,0,0,0,0,0,0,0,0
0,0,0,0,0,0,0,0,0,0,0
0,0,0,0,0,0,0,0,0,0,0
0,0,0,0,0,0,0,0,0,0,0
endlayer

layer
0,0,0,0,0,0,0,0,0,0,0
0,0,0,0,0,0,0,0,0,0,0
0,0,0,0,0,0,0,0,0,0,0
0,0,0,0,0,0,0,0,0,0,0
0,0,0,0,0,0,0,0,0,0,0
0,0,0,0,0,33,0,0,0,0,0
0,0,0,0,0,0,0,0,0,0,0
0,0,0,0,0,0,0,0,0,0,0
0,0,0,0,0,0,0,0,0,0,0
0,0,0,0,0,0,0,0,0,0,0
0,0,0,0,0,0,0,0,0,0,0
endlayer

layer
0,0,0,0,0,0,0,0,0,0,0
0,0,0,0,0,0,0,0,0,0,0
0,0,0,0,0,0,0,0,0,0,0
0,0,0,0,0,0,0,0,0,0,0
0,0,0,0,0,0,0,0,0,0,0
0,0,0,0,0,33,0,0,0,0,0
0,0,0,0,0,0,0,0,0,0,0
0,0,0,0,0,0,0,0,0,0,0
0,0,0,0,0,0,0,0,0,0,0
0,0,0,0,0,0,0,0,0,0,0
0,0,0,0,0,0,0,0,0,0,0
endlayer

layer
0,0,0,0,0,0,0,0,0,0,0
0,0,0,0,0,0,0,0,0,0,0
0,0,0,0,0,0,0,0,0,0,0
0,0,0,0,0,0,0,0,0,0,0
0,0,0,0,0,0,0,0,0,0,0
0,0,0,0,0,7,0,0,0,0,0
0,0,0,0,0,0,0,0,0,0,0
0,0,0,0,0,0,0,0,0,0,0
0,0,0,0,0,0,0,0,0,0,0
0,0,0,0,0,0,0,0,0,0,0
0,0,0,0,0,0,0,0,0,0,0
endlayer

layer
0,0,0,0,0,0,0,0,0,0,0
0,0,0,0,0,0,0,0,0,0,0
0,0,0,0,0,0,0,0,0,0,0
0,0,0,0,0,0,0,0,0,0,0
0,0,0,0,0,0,0,0,0,0,0
0,0,0,0,0,7,0,0,0,0,0
0,0,0,0,0,0,0,0,0,0,0
0,0,0,0,0,0,0,0,0,0,0
0,0,0,0,0,0,0,0,0,0,0
0,0,0,0,0,0,0,0,0,0,0
0,0,0,0,0,0,0,0,0,0,0
endlayer

